"""
URL configuration for videoflix project.

The `urlpatterns` list routes URLs to views. For more information please see:
    https://docs.djangoproject.com/en/5.0/topics/http/urls/
Examples:
Function views
    1. Add an import:  from my_app import views
    2. Add a URL to urlpatterns:  path('', views.home, name='home')
Class-based views
    1. Add an import:  from other_app.views import Home
    2. Add a URL to urlpatterns:  path('', Home.as_view(), name='home')
Including another URLconf
    1. Import the include() function: from django.urls import include, path
    2. Add a URL to urlpatterns:  path('blog/', include('blog.urls'))
"""
from django.conf import settings
from django.contrib import admin
from django.urls import path, include
from django.conf.urls.static import static
# from debug_toolbar.toolbar import debug_toolbar_urls
(env) mathiaskohler91@videoflix-backend:~/projects/videoflix-backend$ python manage.py runserver
AppVideoflixConfig ready method called.
AppVideoflixConfig ready method called.
Watching for file changes with StatReloader
Performing system checks...

Exception in thread django-main-thread:
Traceback (most recent call last):
  File "/usr/lib/python3.8/threading.py", line 932, in _bootstrap_inner
    self.run()
  File "/usr/lib/python3.8/threading.py", line 870, in run
    self._target(*self._args, **self._kwargs)
  File "/home/mathiaskohler91/projects/videoflix-backend/env/lib/python3.8/site-packages/django/utils/autoreload.py", line 64, in wrapper
    fn(*args, **kwargs)
  File "/home/mathiaskohler91/projects/videoflix-backend/env/lib/python3.8/site-packages/django/core/management/commands/runserver.py", line 133, in inner_run
    self.check(display_num_errors=True)
  File "/home/mathiaskohler91/projects/videoflix-backend/env/lib/python3.8/site-packages/django/core/management/base.py", line 485, in check
    all_issues = checks.run_checks(
  File "/home/mathiaskohler91/projects/videoflix-backend/env/lib/python3.8/site-packages/django/core/checks/registry.py", line 88, in run_checks
    new_errors = check(app_configs=app_configs, databases=databases)
  File "/home/mathiaskohler91/projects/videoflix-backend/env/lib/python3.8/site-packages/django/core/checks/urls.py", line 14, in check_url_config
    return check_resolver(resolver)
  File "/home/mathiaskohler91/projects/videoflix-backend/env/lib/python3.8/site-packages/django/core/checks/urls.py", line 24, in check_resolver
    return check_method()
  File "/home/mathiaskohler91/projects/videoflix-backend/env/lib/python3.8/site-packages/django/urls/resolvers.py", line 494, in check
    for pattern in self.url_patterns:
  File "/home/mathiaskohler91/projects/videoflix-backend/env/lib/python3.8/site-packages/django/utils/functional.py", line 57, in __get__
    res = instance.__dict__[self.name] = self.func(instance)
  File "/home/mathiaskohler91/projects/videoflix-backend/env/lib/python3.8/site-packages/django/urls/resolvers.py", line 715, in url_patterns
    patterns = getattr(self.urlconf_module, "urlpatterns", self.urlconf_module)
  File "/home/mathiaskohler91/projects/videoflix-backend/env/lib/python3.8/site-packages/django/utils/functional.py", line 57, in __get__
    res = instance.__dict__[self.name] = self.func(instance)
  File "/home/mathiaskohler91/projects/videoflix-backend/env/lib/python3.8/site-packages/django/urls/resolvers.py", line 708, in urlconf_module
    return import_module(self.urlconf_name)
  File "/usr/lib/python3.8/importlib/__init__.py", line 127, in import_module
    return _bootstrap._gcd_import(name[level:], package, level)
  File "<frozen importlib._bootstrap>", line 1014, in _gcd_import
  File "<frozen importlib._bootstrap>", line 991, in _find_and_load
  File "<frozen importlib._bootstrap>", line 975, in _find_and_load_unlocked
  File "<frozen importlib._bootstrap>", line 671, in _load_unlocked
  File "<frozen importlib._bootstrap_external>", line 848, in exec_module
  File "<frozen importlib._bootstrap>", line 219, in _call_with_frames_removed
  File "/home/mathiaskohler91/projects/videoflix-backend/videoflix/urls.py", line 21, in <module>
    from debug_toolbar.toolbar import debug_toolbar_urls
ImportError: cannot import name 'debug_toolbar_urls' from 'debug_toolbar.toolbar' (/home/mathiaskohler91/projects/videoflix-backend/env/lib/python3.8/site-packages/debug_toolbar/toolbar.py)

urlpatterns = [
    path('admin/', admin.site.urls),
    path('accounts/', include('allauth.urls')), # Django-allauth
    path('auth/', include('app_authentication.urls')),
    path('api/videos/', include('app_videoflix.urls')),
    path('django-rq/', include('django_rq.urls'))
] + debug_toolbar_urls()


# FÃ¼ge die statischen Dateien nur im Entwicklungsmodus hinzu
if settings.DEBUG:
    urlpatterns += static(settings.MEDIA_URL, document_root=settings.MEDIA_ROOT)
